<?xml version="1.0"?>
<robot name="gbot">

    <!-- Map -->
    <!-- <link name="map" />  -->

    <!-- Odom -->
    <!-- <link name="odom" /> 
    <joint name="odom_joint" type="fixed">
        <parent link="map"/>
        <child link="odom"/>
        <origin xyz="0.05 0.0 0.0" rpy="0.0 0.0 0.0"/>
    </joint>  -->

    <!-- Bot Model -->
    <link name="base_footprint" >
        
    </link>

    <link name="base_link">
        <visual>
            <!-- <origin rpy="0 0 0" xyz="0 0 0.2"/> -->
            <geometry>
                <box size="0.6 0.3 0.1"/>
            </geometry>
            <material name="black">
                <color rgba="0.0 0.0 0.0 1.0"/>
            </material>
        </visual>
        <collision>
            <geometry>
                <box size="0.6 0.3 0.1"/>
            </geometry>
        </collision>
        <inertial>
            <mass value="1.0"/>
            <inertia ixx="0.015" ixy="0" ixz="0" iyy="0.0375" iyz="0.0" izz="0.0375"/>
        </inertial>
    </link>
    <joint name="base_link_joint" type="fixed">
        <parent link="base_footprint"/> 
        <child link="base_link"/> 
        <origin xyz="-0.2 0.0 -0.2" rpy="0.0 0.0 0.0"/> 
    </joint> 

    <link name="front_caster_wheel">
        <visual>
            <geometry>
                <box size="0.1 0.1 0.1"/>
            </geometry>
            <material name="black">
                <color rgba="0.0 0.0 0.0 1.0"/>
            </material>
        </visual>
        <collision>
            <geometry>
                <box size="0.1 0.1 0.1"/>
            </geometry>
        </collision>
        <inertial>
            <mass value="1.0"/>
            <inertia ixx="0.00083" ixy="0" ixz="0" iyy="0.00083" iyz="0.0" izz="0.000167"/>
        </inertial>
    </link>
    <joint name="front_caster_of_wheel_joint" type="continuous">
        <axis xyz="0.0 0.0 1.0"/>
        <parent link="base_link"/>
        <child link="front_caster_wheel"/> 
        <origin xyz="0.3 0.0 0.0" rpy="0.0 0.0 0.0"/> 
    </joint>

    <link name="front_wheel">
        <visual>
            <geometry>
                <cylinder radius="0.035" length="0.05"/>
            </geometry>
            <material name="white">
                <color rgba="1.0 1.0 1.0 1.0"/>
            </material>
        </visual>
        <collision>
            <geometry>
                <cylinder radius="0.035" length="0.05"/>
            </geometry>
        </collision>
        <inertial>
            <mass value="1.0"/>
            <inertia ixx="5.1458e-5" ixy="0" ixz="0" iyy="5.1458e-5" iyz="0.0" izz="6.125e-5"/>
        </inertial>
    </link>
    <joint name="front_wheel_joint" type="continuous">
        <axis xyz="0.0 0.0 1.0"/>
        <parent link="front_caster_wheel"/>
        <child link="front_wheel"/>
        <origin xyz="0.05 0.0 -0.15" rpy="-1.5708 0.0 0.0"/> 
    </joint>

    <link name="left_wheel">
        <visual>
            <geometry>
                <cylinder radius="0.035" length="0.05"/>
            </geometry>
            <material name="white">
                <color rgba="1.0 1.0 1.0 1.0"/>
            </material>
        </visual>
        <collision>
            <geometry>
                <cylinder radius="0.035" length="0.05"/>
            </geometry>
        </collision>
        <inertial>
            <mass value="1.0"/>
            <inertia ixx="5.1458e-5" ixy="0" ixz="0" iyy="5.1458e-5" iyz="0.0" izz="6.125e-5"/>  
        </inertial>     
    </link>
    <joint name="left_wheel_joint" type="continuous">
        <axis xyz="0.0 0.0 1.0"/>
        <parent link="base_link"/>
        <child link="left_wheel"/>
        <origin xyz="-0.2 0.1 -0.15" rpy="-1.5708 0.0 0.0"/> 
    </joint>

    <link name="right_wheel">
        <visual>
            <geometry>
                <cylinder radius="0.035" length="0.05"/>
            </geometry>
            <material name="white">
                <color rgba="1.0 1.0 1.0 1.0"/>
            </material>
        </visual>
        <collision>
            <geometry>
                <cylinder radius="0.035" length="0.05"/>
            </geometry>
        </collision>
        <inertial>
            <mass value="1.0"/>
            <inertia ixx="5.1458e-5" ixy="0" ixz="0" iyy="5.1458e-5" iyz="0.0" izz="6.125e-5"/>
        </inertial>
    </link>
    <joint name="right_wheel_joint" type="continuous">
        <axis xyz="0.0 0.0 1.0"/>
        <parent link="base_link"/>
        <child link="right_wheel"/>
        <origin xyz="-0.2 -0.1 -0.15" rpy="-1.5708 0.0 0.0"/> 
    </joint>

    <!-- LADAR -->
    <link name="laser_scanner">
        <visual>
            <geometry>
                <box size="0.1 0.1 0.1"/>
            </geometry>
            <material name="purple">
                <color rgba="1.0 0.0 1.0 1.0"/> 
            </material>
        </visual>
        <collision>
            <geometry>
                <box size="0.1 0.1 0.1"/>
            </geometry>
        </collision> 
        <inertial>
            <mass value="1e-5"/>
            <inertia ixx="1e-6" ixy="0" ixz="0" iyy="1e-6" iyz="0" izz="1e-6"/> 
        </inertial>
    </link>
    <joint name="laser_scanner_joint" type="fixed">
        <axis xyz="0.0 1 0.0"/> 
        <parent link="base_link"/>
        <child link="laser_scanner"/> 
        <origin xyz="0.0 0.0 0.08" rpy="0.0 0.0 0.0"/> 
    </joint>

    <!-- Camera -->
    <link name="camera_link">
         <visual>
            <geometry>
                <box size="0.07 0.07 0.07"/>
            </geometry>
            <material name="blue">
                <color rgba="0.0 0.0 1.0 1.0"/>
            </material>
        </visual>
        <collision>
            <geometry>
                <box size="0.07 0.07 0.07"/>
            </geometry>
        </collision>
        <inertial>
            <mass value="1e-5" />
            <inertia ixx="1e-6" ixy="0" ixz="0" iyy="1e-6" iyz="0" izz="1e-6" />
        </inertial>
    </link>
    <joint name="camera_joint" type="fixed">
        <axis xyz="0 1 0" />
        <origin xyz="0 0 0.15" rpy="0 0.3 0"/>
        <parent link="base_link"/>
        <child link="camera_link"/>
    </joint>

    <!-- IMU -->
    <link name="imu_link">
        <visual>
            <origin xyz="0 0 0" rpy="0 0 0" />
            <geometry>
                <box size = "0.1 0.1 0.1"/> 
            </geometry>
            <material name="yellow">
                <color rgba="1.0 1.0 0.0 1.0"/>
            </material>
        </visual>
        <collision>         
            <geometry>
                <box size = "0.1 0.1 0.1"/> 
            </geometry>
        </collision>  
        <inertial>
            <mass value="1e-5" />
            <inertia ixx="1e-6" ixy="0" ixz="0" iyy="1e-6" iyz="0" izz="1e-6" />
        </inertial>      
    </link>
    <joint name="imu_joint" type="fixed">
        <axis xyz="0 0 0"/>
        <origin xyz="-0.2 0.0 0.08" rpy="0.0 0.0 0.0" />
        <parent link="base_link"/>
        <child link="imu_link" />
    </joint>

    <!-- <link name="imu_tracking">
        <visual>
            <origin xyz="0 0 0" rpy="0 0 0" />
            <geometry>
                <box size = "0.1 0.1 0.1"/> 
            </geometry>
        </visual>
        <collision>         
            <geometry>
                <box size = "0.1 0.1 0.1"/> 
            </geometry>
        </collision>  
        <inertial>
            <mass value="1e-5" />
            <inertia ixx="1e-6" ixy="0" ixz="0" iyy="1e-6" iyz="0" izz="1e-6" />
        </inertial>      
    </link>
    <joint name="imu_tracking_joint" type="fixed">
        <axis xyz="0 0 0"/>
        <origin xyz="-0.3 0.0 0.08" rpy="0 0 0" />
        <parent link="imu_link"/>
        <child link="imu_tracking" />
    </joint> -->





    <!--******************************* Gazebo Simulator Plugins *********************************-->

    <!-- wheel motor drive -->
    <gazebo>
        <plugin name="differential_drive_controller" filename="libgazebo_ros_diff_drive.so">
            <leftJoint>left_wheel_joint</leftJoint>
            <rightJoint>right_wheel_joint</rightJoint> 
            <robotBaseFrame>base_footprint</robotBaseFrame>
            <wheelSeparation>0.25</wheelSeparation>
            <wheelDiameter>0.07</wheelDiameter>
            <publishWheelJoinState>true</publishWheelJoinState>
        </plugin> 
    </gazebo>

    <!-- joint state publisher -->
    <gazebo> 
        <plugin name="joint_state_publisher" filename="libgazebo_ros_joint_state_publisher.so">
            <jointName>front_caster_of_wheel_joint, front_wheel_joint, left_wheel_joint, right_wheel_joint</jointName>
            <!-- <jointName>front_caster_of_wheel_joint, front_wheel_joint</jointName> -->
        </plugin> 
    </gazebo>

    <!-- laser scanner plugin -->
    <gazebo reference="laser_scanner">
        <sensor type="gpu_ray" name="laser">
            <pose>0 0 0 0 0 0</pose>
            <visualize>true</visualize>
            <update_rate>40</update_rate>
            <ray>
                <scan>
                    <horizontal>
                        <sample>720</sample>
                        <resolution>1</resolution>
                        <min_angle>-1.578</min_angle>
                        <max_angle>1.578</max_angle> 
                    </horizontal>
                </scan>
                <range>
                    <min>0.1</min>
                    <max>30</max>
                    <resolution>0.1</resolution>
                </range>
            </ray>
            <plugin name="gpu_laser" filename="libgazebo_ros_gpu_laser.so">
                <topicName>/scan</topicName>
                <frameName>laser_scanner</frameName>
            </plugin>
        </sensor> 
    </gazebo>

    <!-- camera plugin -->
    <gazebo reference="camera_link">
        <sensor type="depth" name="camera">
            <update_rate>30.0</update_rate>
            <camera name="head">
                <horizontal_fov>1.3962634</horizontal_fov>
                <image>
                    <width>800</width>
                    <height>800</height>
                    <format>R8G8B8</format>
                </image>
                <clip>
                    <near>0.02</near>
                    <far>300</far>
                </clip>
                <noise>
                    <type>gaussian</type>
                    <!-- Noise is sampled independently per pixel on each frame.
                        That pixel's noise value is added to each of its color
                        channels, which at that point lie in the range [0,1].  -->
                    <mean>0.0</mean>
                    <stddev>0.007</stddev>
                </noise>
            </camera>
            <plugin name="camera_plugin" filename="libgazebo_ros_openni_kinect.so">
                <baseline>0.2</baseline>
                <alwaysOn>true</alwaysOn>
                <!-- Keep this zero, update_rate in the parent <sensor> tag
                    will control the frame rate. -->
                <updateRate>0.0</updateRate>
                <cameraName>camera_ir</cameraName>
                <imageTopicName>/camera/color/image_raw</imageTopicName>
                <cameraInfoTopicName>/camera/color/camera_info</cameraInfoTopicName>
                <depthImageTopicName>/camera/depth/image_raw</depthImageTopicName>
                <depthImageCameraInfoTopicName>/camera/depth/camera_info</depthImageCameraInfoTopicName>
                <pointCloudTopicName>/camera/depth/points</pointCloudTopicName>
                <frameName>camera_link</frameName>
                <pointCloudCutoff>0.5</pointCloudCutoff>
                <pointCloudCutoffMax>3.0</pointCloudCutoffMax>
                <distortionK1>0</distortionK1>
                <distortionK2>0</distortionK2>
                <distortionK3>0</distortionK3>
                <distortionT1>0</distortionT1>
                <distortionT2>0</distortionT2>
                <CxPrime>0</CxPrime>
                <Cx>0</Cx>
                <Cy>0</Cy>
                <focalLength>0</focalLength>
                <hackBaseline>0</hackBaseline>
            </plugin>
        </sensor>
    </gazebo> 

  <!-- other camera plugin-->
  <!-- <plugin name="camera_controller" filename="libgazebo_ros_camera.so">
                <alwaysOn>true</alwaysOn>
                <updateRate>0.0</updateRate>
                <cameraName>rrbot/camera1</cameraName>
                <imageTopicName>image_raw</imageTopicName>
                <cameraInfoTopicName>camera_info</cameraInfoTopicName>
                <frameName>camera_link</frameName>
                <hackBaseline>0.07</hackBaseline>
                <distortionK1>0.0</distortionK1>
                <distortionK2>0.0</distortionK2>
                <distortionK3>0.0</distortionK3>
                <distortionT1>0.0</distortionT1>
                <distortionT2>0.0</distortionT2>
            </plugin> -->
        



    <!-- imu plugin -->
    <!-- <gazebo>
    <plugin name="imu_plugin" filename="libgazebo_ros_imu.so">
      <alwaysOn>true</alwaysOn>
      <bodyName>base_footprint</bodyName>
      <topicName>imu</topicName>
      <serviceName>imu_service</serviceName>
      <gaussianNoise>0.0</gaussianNoise>
      <updateRate>20.0</updateRate>
    </plugin>
  </gazebo> -->
    <gazebo reference="imu_link">    
        <gravity>true</gravity>
    <sensor name="imu_sensor" type="imu">
      <always_on>true</always_on>
      <update_rate>100</update_rate>
      <visualize>true</visualize>
      <topic>__default_topic__</topic>
      <plugin filename="libgazebo_ros_imu_sensor.so" name="imu_plugin">
        <topicName>imu</topicName>
        <bodyName>imu_link</bodyName>
        <updateRateHZ>10.0</updateRateHZ>
        <gaussianNoise>0.0</gaussianNoise>
        <xyzOffset>0.5 0 0</xyzOffset>
        <rpyOffset>0 0 0</rpyOffset>
        <frameName>imu_link</frameName>
        <initialOrientationAsReference>false</initialOrientationAsReference>
      </plugin>
      <pose>0 0 0 0 0 0</pose>
    </sensor>
    </gazebo>

</robot>